2025-06-23 13:26:56,545 - aiogram.event - ERROR - Cause exception while process update id=817350323 by bot id=8013705189
ValidationError: 1 validation error for SendMessage
text
  Input should be a valid string [type=string_type, input_value=Message(message_id=209, d...=None, user_shared=None), input_type=Message]
    For further information visit https://errors.pydantic.dev/2.10/v/string_type
Traceback (most recent call last):
  File "C:\Users\Dimas-PC\VScode_Projects\Python\Projects\Telegram_Home_Finance\venv\Lib\site-packages\aiogram\dispatcher\dispatcher.py", line 309, in _process_update
    response = await self.feed_update(bot, update, **kwargs)
               ^^^^^^^^^^^^^^^^^^^^^^^^^^^^^^^^^^^^^^^^^^^^^
  File "C:\Users\Dimas-PC\VScode_Projects\Python\Projects\Telegram_Home_Finance\venv\Lib\site-packages\aiogram\dispatcher\dispatcher.py", line 158, in feed_update
    response = await self.update.wrap_outer_middleware(
               ^^^^^^^^^^^^^^^^^^^^^^^^^^^^^^^^^^^^^^^^
  File "C:\Users\Dimas-PC\VScode_Projects\Python\Projects\Telegram_Home_Finance\venv\Lib\site-packages\aiogram\dispatcher\middlewares\error.py", line 25, in __call__
    return await handler(event, data)
           ^^^^^^^^^^^^^^^^^^^^^^^^^^
  File "C:\Users\Dimas-PC\VScode_Projects\Python\Projects\Telegram_Home_Finance\venv\Lib\site-packages\aiogram\dispatcher\middlewares\user_context.py", line 56, in __call__
    return await handler(event, data)
           ^^^^^^^^^^^^^^^^^^^^^^^^^^
  File "C:\Users\Dimas-PC\AppData\Local\Programs\Python\Python311\Lib\contextlib.py", line 222, in __aexit__
    await self.gen.athrow(typ, value, traceback)
  File "C:\Users\Dimas-PC\VScode_Projects\Python\Projects\Telegram_Home_Finance\venv\Lib\site-packages\aiogram\fsm\storage\memory.py", line 69, in lock
    yield
  File "C:\Users\Dimas-PC\VScode_Projects\Python\Projects\Telegram_Home_Finance\venv\Lib\site-packages\aiogram\fsm\middleware.py", line 42, in __call__
    return await handler(event, data)
           ^^^^^^^^^^^^^^^^^^^^^^^^^^
  File "C:\Users\Dimas-PC\VScode_Projects\Python\Projects\Telegram_Home_Finance\venv\Lib\site-packages\aiogram\dispatcher\event\telegram.py", line 121, in trigger
    return await wrapped_inner(event, kwargs)
           ^^^^^^^^^^^^^^^^^^^^^^^^^^^^^^^^^^
  File "C:\Users\Dimas-PC\VScode_Projects\Python\Projects\Telegram_Home_Finance\venv\Lib\site-packages\aiogram\dispatcher\event\handler.py", line 43, in call
    return await wrapped()
           ^^^^^^^^^^^^^^^
  File "C:\Users\Dimas-PC\VScode_Projects\Python\Projects\Telegram_Home_Finance\venv\Lib\site-packages\aiogram\dispatcher\dispatcher.py", line 276, in _listen_update
    return await self.propagate_event(update_type=update_type, event=event, **kwargs)
           ^^^^^^^^^^^^^^^^^^^^^^^^^^^^^^^^^^^^^^^^^^^^^^^^^^^^^^^^^^^^^^^^^^^^^^^^^^
  File "C:\Users\Dimas-PC\VScode_Projects\Python\Projects\Telegram_Home_Finance\venv\Lib\site-packages\aiogram\dispatcher\router.py", line 146, in propagate_event
    return await observer.wrap_outer_middleware(_wrapped, event=event, data=kwargs)
           ^^^^^^^^^^^^^^^^^^^^^^^^^^^^^^^^^^^^^^^^^^^^^^^^^^^^^^^^^^^^^^^^^^^^^^^^
  File "C:\Users\Dimas-PC\VScode_Projects\Python\Projects\Telegram_Home_Finance\venv\Lib\site-packages\aiogram\dispatcher\router.py", line 141, in _wrapped
    return await self._propagate_event(
           ^^^^^^^^^^^^^^^^^^^^^^^^^^^^
  File "C:\Users\Dimas-PC\VScode_Projects\Python\Projects\Telegram_Home_Finance\venv\Lib\site-packages\aiogram\dispatcher\router.py", line 174, in _propagate_event
    response = await router.propagate_event(update_type=update_type, event=event, **kwargs)
               ^^^^^^^^^^^^^^^^^^^^^^^^^^^^^^^^^^^^^^^^^^^^^^^^^^^^^^^^^^^^^^^^^^^^^^^^^^^^
  File "C:\Users\Dimas-PC\VScode_Projects\Python\Projects\Telegram_Home_Finance\venv\Lib\site-packages\aiogram\dispatcher\router.py", line 146, in propagate_event
    return await observer.wrap_outer_middleware(_wrapped, event=event, data=kwargs)
           ^^^^^^^^^^^^^^^^^^^^^^^^^^^^^^^^^^^^^^^^^^^^^^^^^^^^^^^^^^^^^^^^^^^^^^^^
  File "C:\Users\Dimas-PC\VScode_Projects\Python\Projects\Telegram_Home_Finance\venv\Lib\site-packages\aiogram\dispatcher\router.py", line 141, in _wrapped
    return await self._propagate_event(
           ^^^^^^^^^^^^^^^^^^^^^^^^^^^^
  File "C:\Users\Dimas-PC\VScode_Projects\Python\Projects\Telegram_Home_Finance\venv\Lib\site-packages\aiogram\dispatcher\router.py", line 166, in _propagate_event
    response = await observer.trigger(event, **kwargs)
               ^^^^^^^^^^^^^^^^^^^^^^^^^^^^^^^^^^^^^^^
  File "C:\Users\Dimas-PC\VScode_Projects\Python\Projects\Telegram_Home_Finance\venv\Lib\site-packages\aiogram\dispatcher\event\telegram.py", line 121, in trigger
    return await wrapped_inner(event, kwargs)
           ^^^^^^^^^^^^^^^^^^^^^^^^^^^^^^^^^^
  File "C:\Users\Dimas-PC\VScode_Projects\Python\Projects\Telegram_Home_Finance\venv\Lib\site-packages\aiogram\dispatcher\event\handler.py", line 43, in call
    return await wrapped()
           ^^^^^^^^^^^^^^^
  File "C:\Users\Dimas-PC\VScode_Projects\Python\Projects\Telegram_Home_Finance\handlers\handle_records.py", line 171, in get_date_range
    await message.answer(message)
          ^^^^^^^^^^^^^^^^^^^^^^^
  File "C:\Users\Dimas-PC\VScode_Projects\Python\Projects\Telegram_Home_Finance\venv\Lib\site-packages\aiogram\types\message.py", line 2091, in answer
    return SendMessage(
           ^^^^^^^^^^^^
  File "C:\Users\Dimas-PC\VScode_Projects\Python\Projects\Telegram_Home_Finance\venv\Lib\site-packages\pydantic\main.py", line 214, in __init__
    validated_self = self.__pydantic_validator__.validate_python(data, self_instance=self)
                     ^^^^^^^^^^^^^^^^^^^^^^^^^^^^^^^^^^^^^^^^^^^^^^^^^^^^^^^^^^^^^^^^^^^^^
pydantic_core._pydantic_core.ValidationError: 1 validation error for SendMessage
text
  Input should be a valid string [type=string_type, input_value=Message(message_id=209, d...=None, user_shared=None), input_type=Message]
    For further information visit https://errors.pydantic.dev/2.10/v/string_type
2025-06-23 13:27:19,903 - aiogram.event - ERROR - Cause exception while process update id=817350326 by bot id=8013705189
ValidationError: 1 validation error for SendMessage
text
  Input should be a valid string [type=string_type, input_value=Message(message_id=214, d...=None, user_shared=None), input_type=Message]
    For further information visit https://errors.pydantic.dev/2.10/v/string_type
Traceback (most recent call last):
  File "C:\Users\Dimas-PC\VScode_Projects\Python\Projects\Telegram_Home_Finance\venv\Lib\site-packages\aiogram\dispatcher\dispatcher.py", line 309, in _process_update
    response = await self.feed_update(bot, update, **kwargs)
               ^^^^^^^^^^^^^^^^^^^^^^^^^^^^^^^^^^^^^^^^^^^^^
  File "C:\Users\Dimas-PC\VScode_Projects\Python\Projects\Telegram_Home_Finance\venv\Lib\site-packages\aiogram\dispatcher\dispatcher.py", line 158, in feed_update
    response = await self.update.wrap_outer_middleware(
               ^^^^^^^^^^^^^^^^^^^^^^^^^^^^^^^^^^^^^^^^
  File "C:\Users\Dimas-PC\VScode_Projects\Python\Projects\Telegram_Home_Finance\venv\Lib\site-packages\aiogram\dispatcher\middlewares\error.py", line 25, in __call__
    return await handler(event, data)
           ^^^^^^^^^^^^^^^^^^^^^^^^^^
  File "C:\Users\Dimas-PC\VScode_Projects\Python\Projects\Telegram_Home_Finance\venv\Lib\site-packages\aiogram\dispatcher\middlewares\user_context.py", line 56, in __call__
    return await handler(event, data)
           ^^^^^^^^^^^^^^^^^^^^^^^^^^
  File "C:\Users\Dimas-PC\AppData\Local\Programs\Python\Python311\Lib\contextlib.py", line 222, in __aexit__
    await self.gen.athrow(typ, value, traceback)
  File "C:\Users\Dimas-PC\VScode_Projects\Python\Projects\Telegram_Home_Finance\venv\Lib\site-packages\aiogram\fsm\storage\memory.py", line 69, in lock
    yield
  File "C:\Users\Dimas-PC\VScode_Projects\Python\Projects\Telegram_Home_Finance\venv\Lib\site-packages\aiogram\fsm\middleware.py", line 42, in __call__
    return await handler(event, data)
           ^^^^^^^^^^^^^^^^^^^^^^^^^^
  File "C:\Users\Dimas-PC\VScode_Projects\Python\Projects\Telegram_Home_Finance\venv\Lib\site-packages\aiogram\dispatcher\event\telegram.py", line 121, in trigger
    return await wrapped_inner(event, kwargs)
           ^^^^^^^^^^^^^^^^^^^^^^^^^^^^^^^^^^
  File "C:\Users\Dimas-PC\VScode_Projects\Python\Projects\Telegram_Home_Finance\venv\Lib\site-packages\aiogram\dispatcher\event\handler.py", line 43, in call
    return await wrapped()
           ^^^^^^^^^^^^^^^
  File "C:\Users\Dimas-PC\VScode_Projects\Python\Projects\Telegram_Home_Finance\venv\Lib\site-packages\aiogram\dispatcher\dispatcher.py", line 276, in _listen_update
    return await self.propagate_event(update_type=update_type, event=event, **kwargs)
           ^^^^^^^^^^^^^^^^^^^^^^^^^^^^^^^^^^^^^^^^^^^^^^^^^^^^^^^^^^^^^^^^^^^^^^^^^^
  File "C:\Users\Dimas-PC\VScode_Projects\Python\Projects\Telegram_Home_Finance\venv\Lib\site-packages\aiogram\dispatcher\router.py", line 146, in propagate_event
    return await observer.wrap_outer_middleware(_wrapped, event=event, data=kwargs)
           ^^^^^^^^^^^^^^^^^^^^^^^^^^^^^^^^^^^^^^^^^^^^^^^^^^^^^^^^^^^^^^^^^^^^^^^^
  File "C:\Users\Dimas-PC\VScode_Projects\Python\Projects\Telegram_Home_Finance\venv\Lib\site-packages\aiogram\dispatcher\router.py", line 141, in _wrapped
    return await self._propagate_event(
           ^^^^^^^^^^^^^^^^^^^^^^^^^^^^
  File "C:\Users\Dimas-PC\VScode_Projects\Python\Projects\Telegram_Home_Finance\venv\Lib\site-packages\aiogram\dispatcher\router.py", line 174, in _propagate_event
    response = await router.propagate_event(update_type=update_type, event=event, **kwargs)
               ^^^^^^^^^^^^^^^^^^^^^^^^^^^^^^^^^^^^^^^^^^^^^^^^^^^^^^^^^^^^^^^^^^^^^^^^^^^^
  File "C:\Users\Dimas-PC\VScode_Projects\Python\Projects\Telegram_Home_Finance\venv\Lib\site-packages\aiogram\dispatcher\router.py", line 146, in propagate_event
    return await observer.wrap_outer_middleware(_wrapped, event=event, data=kwargs)
           ^^^^^^^^^^^^^^^^^^^^^^^^^^^^^^^^^^^^^^^^^^^^^^^^^^^^^^^^^^^^^^^^^^^^^^^^
  File "C:\Users\Dimas-PC\VScode_Projects\Python\Projects\Telegram_Home_Finance\venv\Lib\site-packages\aiogram\dispatcher\router.py", line 141, in _wrapped
    return await self._propagate_event(
           ^^^^^^^^^^^^^^^^^^^^^^^^^^^^
  File "C:\Users\Dimas-PC\VScode_Projects\Python\Projects\Telegram_Home_Finance\venv\Lib\site-packages\aiogram\dispatcher\router.py", line 166, in _propagate_event
    response = await observer.trigger(event, **kwargs)
               ^^^^^^^^^^^^^^^^^^^^^^^^^^^^^^^^^^^^^^^
  File "C:\Users\Dimas-PC\VScode_Projects\Python\Projects\Telegram_Home_Finance\venv\Lib\site-packages\aiogram\dispatcher\event\telegram.py", line 121, in trigger
    return await wrapped_inner(event, kwargs)
           ^^^^^^^^^^^^^^^^^^^^^^^^^^^^^^^^^^
  File "C:\Users\Dimas-PC\VScode_Projects\Python\Projects\Telegram_Home_Finance\venv\Lib\site-packages\aiogram\dispatcher\event\handler.py", line 43, in call
    return await wrapped()
           ^^^^^^^^^^^^^^^
  File "C:\Users\Dimas-PC\VScode_Projects\Python\Projects\Telegram_Home_Finance\handlers\handle_records.py", line 171, in get_date_range
    await message.answer(message)
          ^^^^^^^^^^^^^^^^^^^^^^^
  File "C:\Users\Dimas-PC\VScode_Projects\Python\Projects\Telegram_Home_Finance\venv\Lib\site-packages\aiogram\types\message.py", line 2091, in answer
    return SendMessage(
           ^^^^^^^^^^^^
  File "C:\Users\Dimas-PC\VScode_Projects\Python\Projects\Telegram_Home_Finance\venv\Lib\site-packages\pydantic\main.py", line 214, in __init__
    validated_self = self.__pydantic_validator__.validate_python(data, self_instance=self)
                     ^^^^^^^^^^^^^^^^^^^^^^^^^^^^^^^^^^^^^^^^^^^^^^^^^^^^^^^^^^^^^^^^^^^^^
pydantic_core._pydantic_core.ValidationError: 1 validation error for SendMessage
text
  Input should be a valid string [type=string_type, input_value=Message(message_id=214, d...=None, user_shared=None), input_type=Message]
    For further information visit https://errors.pydantic.dev/2.10/v/string_type
